<?xml version="1.0" ?>
<sdf version="1.8">
    <model name="aether">
        <link name="base_link"/>

        <link name="chassis_link">
            <pose>0 0 0 0 0 0</pose>
            <inertial>
                <mass>0.05</mass>
                <inertia>
                    <ixx>0.01</ixx>
                    <ixy>0</ixy>
                    <ixz>0</ixz>
                    <iyy>0.01</iyy>
                    <iyz>0</iyz>
                    <izz>0.01</izz>
                </inertia>
            </inertial>
            <visual name="chassis_visual">
                <geometry>
                    <box>
                        <size>0.1 0.1 0.005</size>
                    </box>
                </geometry>
                <material>
                    <ambient>0.5 0.5 1.0 1</ambient>
                    <diffuse>0.5 0.5 1.0 1</diffuse>
                    <specular>0.0 0.0 1.0 1</specular>
                </material>
            </visual>
            <collision name="chassis_collision">
                <geometry>
                    <box>
                        <size>0.1 0.1 0.005</size>
                    </box>
                </geometry>
            </collision>
        </link>

        <link name="left_wheel">
            <pose>0 0 0 0 0 0</pose>
            <inertial>
                <mass>0.05</mass>
                <inertia>
                    <ixx>0.01</ixx>
                    <ixy>0</ixy>
                    <ixz>0</ixz>
                    <iyy>0.01</iyy>
                    <iyz>0</iyz>
                    <izz>0.01</izz>
                </inertia>
            </inertial>
            <visual name="left_wheel_visual">
                <geometry>
                    <sphere>
                        <radius>0.01</radius>
                    </sphere>
                </geometry>
                <material>
                    <ambient>0.2 0.2 0.2 1</ambient>
                    <diffuse>0.2 0.2 0.2 1</diffuse>
                    <specular>0.2 0.2 0.2 1</specular>
                </material>
            </visual>
            <collision name="left_wheel_collision">
                <geometry>
                    <sphere>
                        <radius>0.01</radius>
                    </sphere>
                </geometry>
            </collision>
        </link>

        <link name="right_wheel">
            <pose>0 0 0 0 0 0</pose>
            <inertial>
                <mass>0.05</mass>
                <inertia>
                    <ixx>0.01</ixx>
                    <ixy>0</ixy>
                    <ixz>0</ixz>
                    <iyy>0.01</iyy>
                    <iyz>0</iyz>
                    <izz>0.01</izz>
                </inertia>
            </inertial>
            <visual name="right_wheel_visual">
                <geometry>
                    <sphere>
                        <radius>0.01</radius>
                    </sphere>
                </geometry>
                <material>
                    <ambient>0.2 0.2 0.2 1</ambient>
                    <diffuse>0.2 0.2 0.2 1</diffuse>
                    <specular>0.2 0.2 0.2 1</specular>
                </material>
            </visual>
            <collision name="right_wheel_collision">
                <geometry>
                    <sphere>
                        <radius>0.01</radius>
                    </sphere>
                </geometry>
            </collision>
        </link>

        <link name="lidar_link">
            <pose>0 0 0 0 0 0</pose>
            <inertial>
                <mass>0.01</mass>
                <inertia>
                    <ixx>0.000166667</ixx>
                    <iyy>0.000166667</iyy>
                    <izz>0.000166667</izz>
                </inertia>
            </inertial>
            <collision name="lidar_collision">
                <geometry>
                    <box>
                        <size>0.01 0.01 0.01</size>
                    </box>
                </geometry>
            </collision>
            <visual name="lidar_visual">
                <geometry>
                    <box>
                        <size>0.01 0.01 0.01</size>
                    </box>
                </geometry>
            </visual>
            <sensor name="gpu_lidar" type="gpu_lidar">
                <pose>0 0 0 0 0 0</pose>
                <topic>scan</topic>
                <gz_frame_id>aether/lidar_link</gz_frame_id>
                <update_rate>10</update_rate>
                <lidar>
                    <scan>
                        <horizontal>
                            <samples>640</samples>
                            <resolution>1</resolution>
                            <min_angle>-1.396263</min_angle>
                            <max_angle>1.396263</max_angle>
                        </horizontal>
                        <vertical>
                            <samples>1</samples>
                            <resolution>1</resolution>
                            <min_angle>0.0</min_angle>
                            <max_angle>0.0</max_angle>
                        </vertical>
                    </scan>
                    <range>
                        <min>0.08</min>
                        <max>10.0</max>
                        <resolution>0.01</resolution>
                    </range>
                </lidar>
                <visualize>true</visualize>
            </sensor>
        </link>

        <joint name="chassis_joint" type="fixed">
            <parent>base_link</parent>
            <child>chassis_link</child>
            <!-- <origin>
                <xyz>0.05 0 0.025</xyz>
                <rpy>0 0 0</rpy>
            </origin> -->
            <pose>0.05 0 0.025 0 0 0</pose>
        </joint>

        <joint name="lidar_joint" type="fixed">
            <parent>chassis_link</parent>
            <child>lidar_link</child>
            <pose>0 0 0.05 0 0 0</pose>
        </joint>

        <joint name="left_wheel_joint" type="revolute">
            <parent>chassis_link</parent>
            <child>left_wheel</child>
            <pose>0 -0.75 0 0 0 0</pose>
            <axis>
                <xyz>0 0 1</xyz>
                <limit>
                    <lower>-1.79769e+308</lower>
                    <upper>1.79769e+308</upper>
                </limit>
            </axis>
        </joint>

        <joint name="right_wheel_joint" type="revolute">
            <parent>chassis_link</parent>
            <child>right_wheel</child>
            <pose>0 0.75 0 0 0 0</pose>
            <axis>
                <xyz>0 0 1</xyz>
                <limit>
                    <lower>-1.79769e+308</lower>
                    <upper>1.79769e+308</upper>
                </limit>
            </axis>
        </joint>

        <plugin
        filename="ignition-gazebo-diff-drive-system"
        name="ignition::gazebo::systems::DiffDrive">
            <left_joint>left_wheel_joint</left_joint>
            <right_joint>right_wheel_joint</right_joint>
            <wheel_separation>0.1</wheel_separation>
            <wheel_radius>0.01</wheel_radius>
            <odom_publish_frequency>5</odom_publish_frequency>
            <max_linear_acceleration>5</max_linear_acceleration>
            <min_linear_acceleration>-5</min_linear_acceleration>
            <max_angular_acceleration>5</max_angular_acceleration>
            <min_angular_acceleration>-5</min_angular_acceleration>
            <max_linear_velocity>3.5</max_linear_velocity>
            <min_linear_velocity>-3.5</min_linear_velocity>
            <max_angular_velocity>5</max_angular_velocity>
            <min_angular_velocity>-5</min_angular_velocity>
        </plugin>
    </model>
</sdf>
